Workbook
Name TX_Mean_Overall_Rating: analysis!$E$9
Name TX_Median_Overall_Rating: analysis!$E$10
Name TX_Median_Rating_9_10: analysis!$E$7
Name TX_Median_Readmission: analysis!$E$8
Name TX_Median_Recommend: analysis!$E$4
Name TX_Recommend_Q1: analysis!$E$5
Name TX_Recommend_Q3: analysis!$E$6
Name X_Recommend_Q1: analysis!$E$5

Sheet hospital-cleaned
A1: Facility_ID | B1: Facility_Name | C1: Address | D1: City | E1: State | F1: ZIP_Code | G1: County | H1: Telephone_Number | I1: Hospital_Type | J1: Hospital_Ownership | K1: Emergency_Services | L1: Overall_Rating | M1: Overall_Rating_Raw | N1: Overall_Rating_Footnote
A2: 450002 | B2: THE HOSPITALS OF PROVIDENCE - MEMORIAL CAMPUS | C2: 2001 N OREGON ST | D2: EL PASO | E2: TX | F2: 79902 | G2: EL PASO | H2: (915) 577-6011 | I2: Acute Care Hospitals | J2: Proprietary | K2: Yes | L2: 2 | M2: 2
A3: 450007 | B3: PETERSON REGIONAL MEDICAL CENTER | C3: 551 HILL COUNTRY DRIVE | D3: KERRVILLE | E3: TX | F3: 78028 | G3: KERR | H3: (830) 896-4200 | I3: Acute Care Hospitals | J3: Voluntary non-profit - Private | K3: Yes | L3: 4 | M3: 4
A4: 450010 | B4: UNITED REGIONAL HEALTH CARE SYSTEM | C4: 1600 11TH STREET | D4: WICHITA FALLS | E4: TX | F4: 76301 | G4: WICHITA | H4: (940) 764-7000 | I4: Acute Care Hospitals | J4: Voluntary non-profit - Private | K4: Yes | L4: 3 | M4: 3
A5: 450011 | B5: CHI ST JOSEPH HEALTH REGIONAL HOSPITAL | C5: 2801 FRANCISCAN DR | D5: BRYAN | E5: TX | F5: 77802 | G5: BRAZOS | H5: (979) 776-3912 | I5: Acute Care Hospitals | J5: Voluntary non-profit - Private | K5: Yes | L5: 2 | M5: 2
A6: 450015 | B6: PARKLAND HEALTH & HOSPITAL SYSTEM | C6: 5200 HARRY HINES BLVD | D6: DALLAS | E6: TX | F6: 75235 | G6: DALLAS | H6: (214) 590-8000 | I6: Acute Care Hospitals | J6: Government - Hospital District or Authority | K6: Yes | L6: 3 | M6: 3
A7: 450018 | B7: UNIVERSITY OF TEXAS MEDICAL BRANCH GALVESTON | C7: 301 UNIVERSITY BOULEVARD | D7: GALVESTON | E7: TX | F7: 77555 | G7: GALVESTON | H7: (409) 772-1011 | I7: Acute Care Hospitals | J7: Government - State | K7: Yes | L7: 3 | M7: 3
A8: 450021 | B8: BAYLOR UNIVERSITY MEDICAL CENTER | C8: 3500 GASTON AVE | D8: DALLAS | E8: TX | F8: 75246 | G8: DALLAS | H8: (214) 820-8082 | I8: Acute Care Hospitals | J8: Voluntary non-profit - Private | K8: Yes | L8: 4 | M8: 4
A9: 450023 | B9: CITIZENS MEDICAL CENTER | C9: 2701 HOSPITAL DRIVE | D9: VICTORIA | E9: TX | F9: 77901 | G9: VICTORIA | H9: (361) 573-9181 | I9: Acute Care Hospitals | J9: Voluntary non-profit - Other | K9: Yes | L9: 3 | M9: 3
A10: 450024 | B10: UNIVERSITY MEDICAL CENTER OF EL PASO | C10: 4815 ALAMEDA AVE | D10: EL PASO | E10: TX | F10: 79905 | G10: EL PASO | H10: (915) 521-7602 | I10: Acute Care Hospitals | J10: Physician | K10: Yes | L10: 3 | M10: 3
A11: 450028 | B11: VALLEY BAPTIST MEDICAL CENTER- BROWNSVILLE | C11: 1040 W JEFFERSON ST | D11: BROWNSVILLE | E11: TX | F11: 78520 | G11: CAMERON | H11: (956) 544-1400 | I11: Acute Care Hospitals | J11: Proprietary | K11: Yes | L11: 3 | M11: 3
A12: 450029 | B12: LAREDO MEDICAL CENTER | C12: 1700 EAST SAUNDERS | D12: LAREDO | E12: TX | F12: 78044 | G12: WEBB | H12: (956) 796-5000 | I12: Acute Care Hospitals | J12: Proprietary | K12: Yes | L12: 4 | M12: 4
A13: 450032 | B13: CHRISTUS GOOD SHEPHERD MEDICAL CENTER | C13: 700 E MARSHALL AVE | D13: LONGVIEW | E13: TX | F13: 75601 | G13: GREGG | H13: (903) 927-6712 | I13: Acute Care Hospitals | J13: Voluntary non-profit - Private | K13: Yes | L13: 4 | M13: 4
... A18: 450040 | B18: COVENANT MEDICAL CENTER | C18: 3615 19TH STREET | D18: LUBBOCK | E18: TX | F18: 79410 | G18: LUBBOCK | H18: (806) 725-4431 | I18: Acute Care Hospitals | J18: Voluntary non-profit - Private | K18: Yes | L18: 3 | M18: 3
A19: 450042 | B19: ASCENSION PROVIDENCE | C19: 6901 MEDICAL PARKWAY | D19: WACO | E19: TX | F19: 76712 | G19: MC LENNAN | H19: (254) 751-4000 | I19: Acute Care Hospitals | J19: Voluntary non-profit - Private | K19: Yes | L19: 2 | M19: 2 | N19: 29
A20: 450044 | B20: UT OF TEXAS SOUTHWESTERN UNIVERSITY HOSPITAL - WILLIAM P. CLEMENTS JR. | C20: 6201 HARRY HINES BLVD | D20: DALLAS | E20: TX | F20: 75390 | G20: DALLAS | H20: (214) 633-5555 | I20: Acute Care Hospitals | J20: Government - State | K20: Yes | L20: 4 | M20: 4
A21: 450046 | B21: CHRISTUS SPOHN HOSPITAL CORPUS CHRISTI | C21: 600 ELIZABETH STREET | D21: CORPUS CHRISTI | E21: TX | F21: 78404 | G21: NUECES | H21: (361) 902-4103 | I21: Acute Care Hospitals | J21: Voluntary non-profit - Private | K21: Yes | L21: 3 | M21: 3
A22: 450051 | B22: METHODIST DALLAS MEDICAL CENTER | C22: 1441 NORTH BECKLEY AVENUE | D22: DALLAS | E22: TX | F22: 75203 | G22: DALLAS | H22: (214) 947-8181 | I22: Acute Care Hospitals | J22: Voluntary non-profit - Other | K22: Yes | L22: 3 | M22: 3
A23: 450054 | B23: BAYLOR SCOTT & WHITE MEDICAL CENTER - TEMPLE | C23: 2401 S 31ST ST | D23: TEMPLE | E23: TX | F23: 76508 | G23: BELL | H23: (254) 724-2111 | I23: Acute Care Hospitals | J23: Voluntary non-profit - Private | K23: Yes | L23: 5 | M23: 5
A24: 450055 | B24: ROLLING PLAINS MEMORIAL HOSPITAL | C24: 200 E ARIZONA | D24: SWEETWATER | E24: TX | F24: 79556 | G24: NOLAN | H24: (325) 235-1701 | I24: Acute Care Hospitals | J24: Government - Hospital District or Authority | K24: Yes | M24: Not Available | N24: 16
A25: 450056 | B25: ASCENSION SETON MEDICAL CENTER AUSTIN | C25: 1201 W 38TH ST | D25: AUSTIN | E25: TX | F25: 78705 | G25: TRAVIS | H25: (512) 324-1000 | I25: Acute Care Hospitals | J25: Voluntary non-profit - Private | K25: Yes | L25: 3 | M25: 3 | N25: 29
A26: 450058 | B26: BAPTIST MEDICAL CENTER | C26: 111 DALLAS STREET | D26: SAN ANTONIO | E26: TX | F26: 78205 | G26: BEXAR | H26: (210) 297-8256 | I26: Acute Care Hospitals | J26: Proprietary | K26: Yes | L26: 3 | M26: 3
A27: 450064 | B27: TEXAS HEALTH ARLINGTON MEMORIAL HOSPITAL | C27: 800 W RANDOL MILL RD | D27: ARLINGTON | E27: TX | F27: 76012 | G27: TARRANT | H27: (817) 548-6200 | I27: Acute Care Hospitals | J27: Voluntary non-profit - Private | K27: Yes | L27: 4 | M27: 4
A28: 450068 | B28: MEMORIAL HERMANN - TEXAS MEDICAL CENTER | C28: 6411 FANNIN | D28: HOUSTON | E28: TX | F28: 77030 | G28: HARRIS | H28: (713) 704-3700 | I28: Acute Care Hospitals | J28: Voluntary non-profit - Private | K28: Yes | L28: 4 | M28: 4
A29: 450072 | B29: CHI ST LUKE'S HEALTH BRAZOSPORT | C29: 100 MEDICAL DRIVE | D29: LAKE JACKSON | E29: TX | F29: 77566 | G29: BRAZORIA | H29: (979) 297-4411 | I29: Acute Care Hospitals | J29: Voluntary non-profit - Private | K29: Yes | L29: 4 | M29: 4
A30: 450079 | B30: BAYLOR SCOTT & WHITE MEDICAL CENTER AT IRVING | C30: 1901 N MACARTHUR BLVD | D30: IRVING | E30: TX | F30: 75061 | G30: DALLAS | H30: (972) 579-8100 | I30: Acute Care Hospitals | J30: Voluntary non-profit - Private | K30: Yes | L30: 5 | M30: 5
A31: 450080 | B31: TITUS REGIONAL MEDICAL CENTER | C31: 2001 N JEFFERSON | D31: MOUNT PLEASANT | E31: TX | F31: 75455 | G31: TITUS | H31: (903) 577-6000 | I31: Acute Care Hospitals | J31: Government - Hospital District or Authority | K31: Yes | L31: 3 | M31: 3
A32: 450082 | B32: CHRISTUS SPOHN HOSPITAL BEEVILLE | C32: 1500 E HOUSTON HWY | D32: BEEVILLE | E32: TX | F32: 78102 | G32: BEE | H32: (361) 354-2000 | I32: Acute Care Hospitals | J32: Voluntary non-profit - Private | K32: Yes | L32: 2 | M32: 2
A33: 450083 | B33: UT HEALTH EAST TEXAS TYLER REGIONAL HOSPITAL | C33: 1000 SOUTH BECKHAM AVE | D33: TYLER | E33: TX | F33: 75701 | G33: SMITH | H33: (903) 597-0351 | I33: Acute Care Hospitals | J33: Proprietary | K33: Yes | L33: 2 | M33: 2
A34: 450087 | B34: MEDICAL CITY NORTH HILLS | C34: 4401 BOOTH CALLOWAY ROAD | D34: NORTH RICHLAND HILLS | E34: TX | F34: 76180 | G34: TARRANT | H34: (817) 255-1000 | I34: Acute Care Hospitals | J34: Proprietary | K34: Yes | L34: 2 | M34: 2
A35: 450090 | B35: NORTH TEXAS MEDICAL CENTER | C35: 1900 HOSPITAL BLVD | D35: GAINESVILLE | E35: TX | F35: 76240 | G35: COOKE | H35: (940) 612-8600 | I35: Acute Care Hospitals | J35: Voluntary non-profit - Private | K35: Yes | L35: 4 | M35: 4
A36: 450092 | B36: FORT DUNCAN MEDICAL CENTER | C36: 3333 N FOSTER MALDONADO BLVD | D36: EAGLE PASS | E36: TX | F36: 78852 | G36: MAVERICK | H36: (830) 773-5321 | I36: Acute Care Hospitals | J36: Proprietary | K36: Yes | L36: 3 | M36: 3
A37: 450097 | B37: HCA HOUSTON HEALTHCARE SOUTHEAST | C37: 4000 SPENCER HWY | D37: PASADENA | E37: TX | F37: 77504 | G37: HARRIS | H37: (713) 359-1000 | I37: Acute Care Hospitals | J37: Proprietary | K37: Yes | L37: 3 | M37: 3
... A43: 450119 | B43: SOUTH TEXAS HEALTH SYSTEM | C43: 1102 W TRENTON ROAD | D43: EDINBURG | E43: TX | F43: 78539 | G43: HIDALGO | H43: (956) 632-4000 | I43: Acute Care Hospitals | J43: Proprietary | K43: Yes | L43: 4 | M43: 4
A44: 450124 | B44: DELL SETON MED CENTER AT THE UNIVERSITY OF TX | C44: 601 E 15TH STREET | D44: AUSTIN | E44: TX | F44: 78701 | G44: TRAVIS | H44: (512) 324-7000 | I44: Acute Care Hospitals | J44: Voluntary non-profit - Private | K44: No | L44: 4 | M44: 4 | N44: 29
A45: 450128 | B45: KNAPP MEDICAL CENTER | C45: 1401 EAST EIGHT STREET | D45: WESLACO | E45: TX | F45: 78596 | G45: HIDALGO | H45: (956) 968-8567 | I45: Acute Care Hospitals | J45: Voluntary non-profit - Private | K45: Yes | L45: 5 | M45: 5
A46: 450132 | B46: MEDICAL CENTER HOSPITAL | C46: 500 W 4TH STREET | D46: ODESSA | E46: TX | F46: 79761 | G46: ECTOR | H46: (432) 640-4000 | I46: Acute Care Hospitals | J46: Government - Hospital District or Authority | K46: Yes | L46: 3 | M46: 3
A47: 450133 | B47: MIDLAND MEMORIAL HOSPITAL | C47: 400 ROSALIND REDFERN GROVER PARKWAY | D47: MIDLAND | E47: TX | F47: 79701 | G47: MIDLAND | H47: (432) 685-1111 | I47: Acute Care Hospitals | J47: Government - Hospital District or Authority | K47: Yes | L47: 1 | M47: 1
A48: 450135 | B48: TEXAS HEALTH HARRIS METHODIST FORT WORTH | C48: 1301 PENNSYLVANIA AVENUE | D48: FORT WORTH | E48: TX | F48: 76104 | G48: TARRANT | H48: (817) 250-2100 | I48: Acute Care Hospitals | J48: Voluntary non-profit - Private | K48: Yes | L48: 4 | M48: 4
A49: 450137 | B49: BAYLOR SCOTT AND WHITE ALL SAINTS MEDICAL CENTER | C49: 1400 EIGHTH AVE | D49: FORT WORTH | E49: TX | F49: 76104 | G49: TARRANT | H49: (817) 926-2544 | I49: Acute Care Hospitals | J49: Voluntary non-profit - Private | K49: No | L49: 4 | M49: 4
...

Sheet hcahps-cleaned
A1: Facility_ID | B1: Nurse_Communication_Pct | C1: Doctor_Communication_Pct | D1: Medicine_Communication_Pct | E1: Discharge_Info_Pct | F1: Hospital_Rating_9_10_Pct | G1: Definitely_Recommend_Pct | H1: Completed_Surveys_Raw | I1: Survey_Response_Rate_Pct | J1: HCAHPS_Start_Date | K1: HCAHPS_End_Date
A2: 450002 | B2: 64 | C2: 68 | D2: 54 | E2: 82 | F2: 52 | G2: 54 | H2: 529 | I2: 10 | J2: 45474 | K2: 45838
A3: 450007 | B3: 81 | C3: 78 | D3: 64 | E3: 91 | F3: 81 | G3: 80 | H3: 750 | I3: 22 | J3: 45474 | K3: 45838
A4: 450010 | B4: 79 | C4: 75 | D4: 58 | E4: 87 | F4: 71 | G4: 71 | H4: 505 | I4: 20 | J4: 45474 | K4: 45838
A5: 450011 | B5: 77 | C5: 77 | D5: 61 | E5: 83 | F5: 66 | G5: 66 | H5: 1177 | I5: 13 | J5: 45474 | K5: 45838
A6: 450015 | B6: 73 | C6: 76 | D6: 56 | E6: 85 | F6: 70 | G6: 70 | H6: 1727 | I6: 6 | J6: 45474 | K6: 45838
A7: 450018 | B7: 77 | C7: 76 | D7: 61 | E7: 85 | F7: 74 | G7: 72 | H7: 1342 | I7: 11 | J7: 45474 | K7: 45838
A8: 450021 | B8: 78 | C8: 80 | D8: 60 | E8: 87 | F8: 71 | G8: 74 | H8: 2284 | I8: 12 | J8: 45474 | K8: 45838
A9: 450023 | B9: 80 | C9: 79 | D9: 61 | E9: 83 | F9: 73 | G9: 73 | H9: 882 | I9: 19 | J9: 45474 | K9: 45838
A10: 450024 | B10: 73 | C10: 75 | D10: 56 | E10: 84 | F10: 68 | G10: 70 | H10: 2423 | I10: 24 | J10: 45474 | K10: 45838
A11: 450028 | B11: 66 | C11: 69 | D11: 51 | E11: 81 | F11: 58 | G11: 58 | H11: 410 | I11: 8 | J11: 45474 | K11: 45838
A12: 450029 | B12: 74 | C12: 75 | D12: 56 | E12: 80 | F12: 59 | G12: 59 | H12: 387 | I12: 7 | J12: 45474 | K12: 45838
A13: 450032 | B13: 81 | C13: 78 | D13: 67 | E13: 85 | F13: 72 | G13: 71 | H13: 486 | I13: 15 | J13: 45474 | K13: 45838
... A63: 450196 | B63: 75 | C63: 74 | D63: 58 | E63: 82 | F63: 58 | G63: 55 | H63: 1125 | I63: 17 | J63: 45474 | K63: 45838
A64: 450200 | H64: Not Available | J64: 45474 | K64: 45838
A65: 450203 | B65: 77 | C65: 77 | D65: 58 | E65: 83 | F65: 68 | G65: 64 | H65: 618 | I65: 19 | J65: 45474 | K65: 45838
A66: 450209 | B66: 77 | C66: 72 | D66: 57 | E66: 82 | F66: 65 | G66: 66 | H66: 649 | I66: 12 | J66: 45474 | K66: 45838
A67: 450210 | B67: 94 | C67: 89 | D67: 80 | E67: 95 | F67: 85 | G67: 74 | H67: 70 | I67: 22 | J67: 45474 | K67: 45838
A68: 450211 | B68: 77 | C68: 79 | D68: 62 | E68: 85 | F68: 71 | G68: 72 | H68: 509 | I68: 16 | J68: 45474 | K68: 45838
A69: 450213 | B69: 76 | C69: 78 | D69: 59 | E69: 85 | F69: 75 | G69: 76 | H69: 2306 | I69: 22 | J69: 45474 | K69: 45838
A70: 450222 | B70: 72 | C70: 67 | D70: 54 | E70: 77 | F70: 61 | G70: 57 | H70: 554 | I70: 13 | J70: 45474 | K70: 45838
A71: 450229 | B71: 74 | C71: 77 | D71: 58 | E71: 89 | F71: 64 | G71: 65 | H71: 361 | I71: 17 | J71: 45474 | K71: 45838
A72: 450231 | B72: 77 | C72: 76 | D72: 56 | E72: 84 | F72: 73 | G72: 76 | H72: 1324 | I72: 21 | J72: 45474 | K72: 45838
A73: 450235 | B73: 84 | C73: 83 | D73: 71 | E73: 92 | F73: 81 | G73: 72 | H73: 52 | I73: 14 | J73: 45474 | K73: 45838
A74: 450236 | B74: 86 | C74: 80 | D74: 64 | E74: 88 | F74: 80 | G74: 76 | H74: 357 | I74: 18 | J74: 45474 | K74: 45838
A75: 450237 | B75: 75 | C75: 78 | D75: 59 | E75: 86 | F75: 70 | G75: 70 | H75: 470 | I75: 15 | J75: 45474 | K75: 45838
A76: 450241 | B76: 88 | C76: 79 | D76: 74 | E76: 90 | F76: 73 | G76: 69 | H76: 34 | I76: 13 | J76: 45474 | K76: 45838
A77: 450253 | H77: Not Available | J77: 45474 | K77: 45838
A78: 450272 | B78: 77 | C78: 83 | D78: 60 | E78: 85 | F78: 70 | G78: 69 | H78: 569 | I78: 16 | J78: 45474 | K78: 45838
A79: 450289 | B79: 77 | C79: 80 | D79: 57 | E79: 84 | F79: 72 | G79: 71 | H79: 524 | I79: 5 | J79: 45474 | K79: 45838
A80: 450292 | B80: 86 | C80: 81 | D80: 68 | E80: 89 | F80: 73 | G80: 71 | H80: 126 | I80: 17 | J80: 45474 | K80: 45838
A81: 450324 | B81: 79 | C81: 75 | D81: 61 | E81: 85 | F81: 65 | G81: 67 | H81: 597 | I81: 17 | J81: 45474 | K81: 45838
A82: 450330 | B82: 75 | C82: 75 | D82: 55 | E82: 82 | F82: 62 | G82: 59 | H82: 246 | I82: 15 | J82: 45474 | K82: 45838
A83: 450346 | B83: 77 | C83: 74 | D83: 59 | E83: 85 | F83: 70 | G83: 69 | H83: 1399 | I83: 12 | J83: 45474 | K83: 45838
A84: 450347 | B84: 75 | C84: 77 | D84: 58 | E84: 86 | F84: 66 | G84: 63 | H84: 318 | I84: 18 | J84: 45474 | K84: 45838
A85: 450351 | B85: 86 | C85: 83 | D85: 67 | E85: 90 | F85: 75 | G85: 74 | H85: 182 | I85: 18 | J85: 45474 | K85: 45838
A86: 450352 | B86: 73 | C86: 73 | D86: 53 | E86: 84 | F86: 63 | G86: 63 | H86: 774 | I86: 15 | J86: 45474 | K86: 45838
A87: 450358 | B87: 78 | C87: 81 | D87: 60 | E87: 88 | F87: 79 | G87: 82 | H87: 6495 | I87: 20 | J87: 45474 | K87: 45838
A88: 450369 | B88: 96 | C88: 98 | D88: 91 | E88: 90 | F88: 92 | G88: 92 | H88: 92 | I88: 23 | J88: 45474 | K88: 45838
A89: 450370 | B89: 79 | C89: 77 | D89: 62 | E89: 83 | F89: 73 | G89: 73 | H89: 124 | I89: 22 | J89: 45474 | K89: 45838
...

Sheet readmission-cleaned
A1: Facility_ID | B1: Readmission_Rate_Pct | C1: Readmission_Comparison | D1: Readmission_Denominator | E1: Readmission_Lower_Estimate | F1: Readmission_Higher_Estimate | G1: Readmission_Footnote | H1: Readmission_Start_Date | I1: Readmission_End_Date
A2: 450002 | B2: 15.3 | C2: No Different | D2: 628 | E2: 13.9 | F2: 17 | H2: 45108 | I2: 45473
A3: 450007 | B3: 15 | C3: No Different | D3: 1340 | E3: 13.7 | F3: 16.4 | H3: 45108 | I3: 45473
A4: 450010 | B4: 15.6 | C4: No Different | D4: 3943 | E4: 14.7 | F4: 16.4 | H4: 45108 | I4: 45473
A5: 450011 | B5: 14.9 | C5: No Different | D5: 2792 | E5: 13.9 | F5: 15.9 | H5: 45108 | I5: 45473
A6: 450015 | B6: 14.7 | C6: No Different | D6: 893 | E6: 13.5 | F6: 16.1 | H6: 45108 | I6: 45473
A7: 450018 | B7: 16 | C7: No Different | D7: 3474 | E7: 15 | F7: 16.9 | H7: 45108 | I7: 45473
A8: 450021 | B8: 13.9 | C8: Better | D8: 4591 | E8: 13.1 | F8: 14.7 | H8: 45108 | I8: 45473
A9: 450023 | B9: 14.7 | C9: No Different | D9: 1380 | E9: 13.5 | F9: 16.1 | H9: 45108 | I9: 45473
A10: 450024 | B10: 15.4 | C10: No Different | D10: 906 | E10: 14.1 | F10: 16.8 | H10: 45108 | I10: 45473
A11: 450028 | B11: 15.4 | C11: No Different | D11: 710 | E11: 14 | F11: 16.9 | H11: 45108 | I11: 45473
A12: 450029 | B12: 15.1 | C12: No Different | D12: 1371 | E12: 13.9 | F12: 16.2 | H12: 45108 | I12: 45473
A13: 450032 | B13: 16.4 | C13: Worse | D13: 2659 | E13: 15.4 | F13: 17.4 | H13: 45108 | I13: 45473
... A18: 450040 | B18: 13.5 | C18: Better | D18: 3522 | E18: 12.7 | F18: 14.5 | H18: 45108 | I18: 45473
A19: 450042 | B19: 14.2 | C19: No Different | D19: 1091 | E19: 13 | F19: 15.1 | G19: 29 | H19: 45108 | I19: 45473
A20: 450044 | B20: 15.9 | C20: Worse | D20: 5428 | E20: 15.1 | F20: 16.7 | H20: 45108 | I20: 45473
A21: 450046 | B21: 14.4 | C21: No Different | D21: 2388 | E21: 13.5 | F21: 15.5 | H21: 45108 | I21: 45473
A22: 450051 | B22: 14.1 | C22: No Different | D22: 1227 | E22: 13 | F22: 15.3 | H22: 45108 | I22: 45473
A23: 450054 | B23: 14.9 | C23: No Different | D23: 4120 | E23: 14.2 | F23: 15.9 | H23: 45108 | I23: 45473
A24: 450055 | B24: 15.2 | C24: No Different | D24: 132 | E24: 13.5 | F24: 17 | H24: 45108 | I24: 45473
A25: 450056 | B25: 14.3 | C25: No Different | D25: 1134 | E25: 13 | F25: 15.1 | G25: 29 | H25: 45108 | I25: 45473
A26: 450058 | B26: 14.3 | C26: No Different | D26: 5603 | E26: 13.5 | F26: 15.1 | H26: 45108 | I26: 45473
A27: 450064 | B27: 15.3 | C27: No Different | D27: 1431 | E27: 14.1 | F27: 16.6 | H27: 45108 | I27: 45473
A28: 450068 | B28: 14.6 | C28: No Different | D28: 3979 | E28: 13.7 | F28: 15.5 | H28: 45108 | I28: 45473
A29: 450072 | B29: 15.1 | C29: No Different | D29: 532 | E29: 13.5 | F29: 16.8 | H29: 45108 | I29: 45473
A30: 450079 | B30: 14.8 | C30: No Different | D30: 1424 | E30: 13.6 | F30: 16 | H30: 45108 | I30: 45473
A31: 450080 | B31: 15.2 | C31: No Different | D31: 515 | E31: 13.9 | F31: 16.7 | H31: 45108 | I31: 45473
A32: 450082 | B32: 15.4 | C32: No Different | D32: 152 | E32: 13.7 | F32: 17.3 | H32: 45108 | I32: 45473
A33: 450083 | B33: 15.4 | C33: No Different | D33: 4047 | E33: 14.5 | F33: 16.3 | H33: 45108 | I33: 45473
A34: 450087 | B34: 15.3 | C34: No Different | D34: 1041 | E34: 14.1 | F34: 16.8 | H34: 45108 | I34: 45473
A35: 450090 | B35: 14.9 | C35: No Different | D35: 412 | E35: 13.3 | F35: 16.5 | H35: 45108 | I35: 45473
A36: 450092 | B36: 15 | C36: No Different | D36: 229 | E36: 13.4 | F36: 17 | H36: 45108 | I36: 45473
A37: 450097 | B37: 15.6 | C37: No Different | D37: 775 | E37: 14.3 | F37: 17.1 | H37: 45108 | I37: 45473
... A43: 450119 | B43: 15.9 | C43: No Different | D43: 1524 | E43: 14.8 | F43: 17.2 | H43: 45108 | I43: 45473
A44: 450124 | B44: 14.9 | C44: No Different | D44: 464 | E44: 13.5 | F44: 16.3 | G44: 29 | H44: 45108 | I44: 45473
A45: 450128 | B45: 14.4 | C45: No Different | D45: 468 | E45: 12.9 | F45: 15.9 | H45: 45108 | I45: 45473
A46: 450132 | B46: 15 | C46: No Different | D46: 1808 | E46: 13.9 | F46: 16.1 | H46: 45108 | I46: 45473
A47: 450133 | B47: 14.9 | C47: No Different | D47: 1564 | E47: 13.7 | F47: 16 | H47: 45108 | I47: 45473
A48: 450135 | B48: 14.4 | C48: No Different | D48: 5590 | E48: 13.7 | F48: 15.2 | H48: 45108 | I48: 45473
A49: 450137 | B49: 15.8 | C49: No Different | D49: 2563 | E49: 14.9 | F49: 16.8 | H49: 45108 | I49: 45473
...

Sheet merged-cleaned
A1: Facility_ID | B1: Facility_Name | C1: Address | D1: City | E1: State | F1: ZIP_Code | G1: County | H1: Telephone_Number | I1: Hospital_Type | J1: Hospital_Ownership | K1: Emergency_Services | L1: Overall_Rating | M1: Overall_Rating_Raw | N1: Overall_Rating_Footnote | O1: Nurse_Communication_Pct | P1: Doctor_Communication_Pct | Q1: Medicine_Communication_Pct | R1: Discharge_Info_Pct | S1: Hospital_Rating_9_10_Pct | T1: Definitely_Recommend_Pct | U1: Completed_Surveys_Raw | V1: Survey_Response_Rate_Pct | W1: HCAHPS_Start_Date | X1: HCAHPS_End_Date | Y1: Readmission_Rate_Pct | Z1: Readmission_Comparison | AA1: Readmission_Denominator | AB1: Readmission_Lower_Estimate | AC1: Readmission_Higher_Estimate | AD1: Readmission_Footnote | AE1: Readmission_Start_Date | AF1: Readmission_End_Date | AG1: Overall_Rating_Available | AH1: HCAHPS_Available | AI1: Readmission_Available | AJ1: Rating_Group | AK1: Low_Rating_Flag | AL1: Below_TX_Median_Recommend_Flag | AM1: Worse_Readmission_Flag | AN1: Signals_Available_Count | AO1: Screening_Signal_Count | AP1: Priority_Tier | AQ1: Recommendation_Quartile | AR1: Recommend_vs_TX_Median | AS1: Readmission_vs_TX_Median
A2: 450002 | B2: THE HOSPITALS OF PROVIDENCE - MEMORIAL CAMPUS | C2: 2001 N OREGON ST | D2: EL PASO | E2: TX | F2: 79902 | G2: EL PASO | H2: (915) 577-6011 | I2: Acute Care Hospitals | J2: Proprietary | K2: Yes | L2: 2 | M2: 2 | O2: 64 | P2: 68 | Q2: 54 | R2: 82 | S2: 52 | T2: 54 | U2: 529 | V2: 10 | W2: 45474 | X2: 45838 | Y2: 15.3 | Z2: No Different | AA2: 628 | AB2: 13.9 | AC2: 17 | AE2: 45108 | AF2: 45473 | AG2: TRUE | AH2: TRUE | AI2: TRUE | AJ2: =IF(tblMergedCleaned[[#This Row],[Overall_Rating]]= "", "Unavailable", IF(tblMergedCleaned[[#This Row],[Overall_Rating]]<= 2, "Low (1-2)", IF(tblMergedCleaned[[#This Row],[Overall_Rating]]= 3, "Middle (3)", "High (4-5)" ) ) ) -> Low (1-2) | AK2: {=IF( tblMergedCleaned[[#This Row],[Overall_Rating]]="", "", --(tblMergedCleaned[[#This Row],[Overall_Rating]]<=2) )} -> 1 | AL2: =IF( tblMergedCleaned[[#This Row],[Definitely_Recommend_Pct]]="", "", --(tblMergedCleaned[[#This Row],[Definitely_Recommend_Pct]]<TX_Median_Recommend) ) -> 1 | AM2: =IF( tblMergedCleaned[[#This Row],[Readmission_Comparison]]="", "", --(tblMergedCleaned[[#This Row],[Readmission_Comparison]]="Worse") ) -> 0 | AN2: =COUNT( tblMergedCleaned[[#This Row],[Low_Rating_Flag]:[Worse_Readmission_Flag]] ) -> 3 | AO2: =SUM( tblMergedCleaned[[#This Row],[Low_Rating_Flag]:[Worse_Readmission_Flag]] ) -> 2 | AP2: =IF( tblMergedCleaned[[#This Row],[Signals_Available_Count]]<3, "Limited data", IF( tblMergedCleaned[[#This Row],[Screening_Signal_Count]]=3, "Priority 1", IF( tblMergedCleaned[[#This Row],[Screening_Signal_Count]]=2, "Priority 2", IF( tblMergedCleaned[[#This Row],[Screening_Signal_Count]]=1, "Monitor", "No flagged signals" ) ) ) ) -> Priority 2 | AQ2: =IF( tblMergedCleaned[[#This Row],[Definitely_Recommend_Pct]]="", "Unavailable", IF( tblMergedCleaned[[#This Row],[Definitely_Recommend_Pct]]<=TX_Recommend_Q1, "Q1 - Lowest", IF( tblMergedCleaned[[#This Row],[Definitely_Recommend_Pct]]<=TX_Median_Recommend, "Q2", IF( tblMergedCleaned[[#This Row],[Definitely_Recommend_Pct]]<=TX_Recommend_Q3, "Q3", "Q4 - Highest" ) ) ) ) -> Q1 - Lowest | AR2: =IF( tblMergedCleaned[[#This Row],[Definitely_Recommend_Pct]]="", "", tblMergedCleaned[[#This Row],[Definitely_Recommend_Pct]]-TX_Median_Recommend ) -> -17 | AS2: =IF( tblMergedCleaned[[#This Row],[Readmission_Rate_Pct]]="", "", tblMergedCleaned[[#This Row],[Readmission_Rate_Pct]]-TX_Median_Readmission ) -> 0.4
A3: 450007 | B3: PETERSON REGIONAL MEDICAL CENTER | C3: 551 HILL COUNTRY DRIVE | D3: KERRVILLE | E3: TX | F3: 78028 | G3: KERR | H3: (830) 896-4200 | I3: Acute Care Hospitals | J3: Voluntary non-profit - Private | K3: Yes | L3: 4 | M3: 4 | O3: 81 | P3: 78 | Q3: 64 | R3: 91 | S3: 81 | T3: 80 | U3: 750 | V3: 22 | W3: 45474 | X3: 45838 | Y3: 15 | Z3: No Different | AA3: 1340 | AB3: 13.7 | AC3: 16.4 | AE3: 45108 | AF3: 45473 | AG3: TRUE | AH3: TRUE | AI3: TRUE | AJ3: =IF(tblMergedCleaned[[#This Row],[Overall_Rating]]= "", "Unavailable", IF(tblMergedCleaned[[#This Row],[Overall_Rating]]<= 2, "Low (1-2)", IF(tblMergedCleaned[[#This Row],[Overall_Rating]]= 3, "Middle (3)", "High (4-5)" ) ) ) -> High (4-5) | AK3: {=IF( tblMergedCleaned[[#This Row],[Overall_Rating]]="", "", --(tblMergedCleaned[[#This Row],[Overall_Rating]]<=2) )} -> 0 | AL3: =IF( tblMergedCleaned[[#This Row],[Definitely_Recommend_Pct]]="", "", --(tblMergedCleaned[[#This Row],[Definitely_Recommend_Pct]]<TX_Median_Recommend) ) -> 0 | AM3: =IF( tblMergedCleaned[[#This Row],[Readmission_Comparison]]="", "", --(tblMergedCleaned[[#This Row],[Readmission_Comparison]]="Worse") ) -> 0 | AN3: =COUNT( tblMergedCleaned[[#This Row],[Low_Rating_Flag]:[Worse_Readmission_Flag]] ) -> 3 | AO3: =SUM( tblMergedCleaned[[#This Row],[Low_Rating_Flag]:[Worse_Readmission_Flag]] ) -> 0 | AP3: =IF( tblMergedCleaned[[#This Row],[Signals_Available_Count]]<3, "Limited data", IF( tblMergedCleaned[[#This Row],[Screening_Signal_Count]]=3, "Priority 1", IF( tblMergedCleaned[[#This Row],[Screening_Signal_Count]]=2, "Priority 2", IF( tblMergedCleaned[[#This Row],[Screening_Signal_Count]]=1, "Monitor", "No flagged signals" ) ) ) ) -> No flagged signals | AQ3: =IF( tblMergedCleaned[[#This Row],[Definitely_Recommend_Pct]]="", "Unavailable", IF( tblMergedCleaned[[#This Row],[Definitely_Recommend_Pct]]<=TX_Recommend_Q1, "Q1 - Lowest", IF( tblMergedCleaned[[#This Row],[Definitely_Recommend_Pct]]<=TX_Median_Recommend, "Q2", IF( tblMergedCleaned[[#This Row],[Definitely_Recommend_Pct]]<=TX_Recommend_Q3, "Q3", "Q4 - Highest" ) ) ) ) -> Q4 - Highest | AR3: =IF( tblMergedCleaned[[#This Row],[Definitely_Recommend_Pct]]="", "", tblMergedCleaned[[#This Row],[Definitely_Recommend_Pct]]-TX_Median_Recommend ) -> 9 | AS3: =IF( tblMergedCleaned[[#This Row],[Readmission_Rate_Pct]]="", "", tblMergedCleaned[[#This Row],[Readmission_Rate_Pct]]-TX_Median_Readmission ) -> 0.1
A4: 450010 | B4: UNITED REGIONAL HEALTH CARE SYSTEM | C4: 1600 11TH STREET | D4: WICHITA FALLS | E4: TX | F4: 76301 | G4: WICHITA | H4: (940) 764-7000 | I4: Acute Care Hospitals | J4: Voluntary non-profit - Private | K4: Yes | L4: 3 | M4: 3 | O4: 79 | P4: 75 | Q4: 58 | R4: 87 | S4: 71 | T4: 71 | U4: 505 | V4: 20 | W4: 45474 | X4: 45838 | Y4: 15.6 | Z4: No Different | AA4: 3943 | AB4: 14.7 | AC4: 16.4 | AE4: 45108 | AF4: 45473 | AG4: TRUE | AH4: TRUE | AI4: TRUE | AJ4: =IF(tblMergedCleaned[[#This Row],[Overall_Rating]]= "", "Unavailable", IF(tblMergedCleaned[[#This Row],[Overall_Rating]]<= 2, "Low (1-2)", IF(tblMergedCleaned[[#This Row],[Overall_Rating]]= 3, "Middle (3)", "High (4-5)" ) ) ) -> Middle (3) | AK4: {=IF( tblMergedCleaned[[#This Row],[Overall_Rating]]="", "", --(tblMergedCleaned[[#This Row],[Overall_Rating]]<=2) )} -> 0 | AL4: =IF( tblMergedCleaned[[#This Row],[Definitely_Recommend_Pct]]="", "", --(tblMergedCleaned[[#This Row],[Definitely_Recommend_Pct]]<TX_Median_Recommend) ) -> 0 | AM4: =IF( tblMergedCleaned[[#This Row],[Readmission_Comparison]]="", "", --(tblMergedCleaned[[#This Row],[Readmission_Comparison]]="Worse") ) -> 0 | AN4: =COUNT( tblMergedCleaned[[#This Row],[Low_Rating_Flag]:[Worse_Readmission_Flag]] ) -> 3 | AO4: =SUM( tblMergedCleaned[[#This Row],[Low_Rating_Flag]:[Worse_Readmission_Flag]] ) -> 0 | AP4: =IF( tblMergedCleaned[[#This Row],[Signals_Available_Count]]<3, "Limited data", IF( tblMergedCleaned[[#This Row],[Screening_Signal_Count]]=3, "Priority 1", IF( tblMergedCleaned[[#This Row],[Screening_Signal_Count]]=2, "Priority 2", IF( tblMergedCleaned[[#This Row],[Screening_Signal_Count]]=1, "Monitor", "No flagged signals" ) ) ) ) -> No flagged signals | AQ4: =IF( tblMergedCleaned[[#This Row],[Definitely_Recommend_Pct]]="", "Unavailable", IF( tblMergedCleaned[[#This Row],[Definitely_Recommend_Pct]]<=TX_Recommend_Q1, "Q1 - Lowest", IF( tblMergedCleaned[[#This Row],[Definitely_Recommend_Pct]]<=TX_Median_Recommend, "Q2", IF( tblMergedCleaned[[#This Row],[Definitely_Recommend_Pct]]<=TX_Recommend_Q3, "Q3", "Q4 - Highest" ) ) ) ) -> Q2 | AR4: =IF( tblMergedCleaned[[#This Row],[Definitely_Recommend_Pct]]="", "", tblMergedCleaned[[#This Row],[Definitely_Recommend_Pct]]-TX_Median_Recommend ) -> 0 | AS4: =IF( tblMergedCleaned[[#This Row],[Readmission_Rate_Pct]]="", "", tblMergedCleaned[[#This Row],[Readmission_Rate_Pct]]-TX_Median_Readmission ) -> 0.7
A5: 450011 | B5: CHI ST JOSEPH HEALTH REGIONAL HOSPITAL | C5: 2801 FRANCISCAN DR | D5: BRYAN | E5: TX | F5: 77802 | G5: BRAZOS | H5: (979) 776-3912 | I5: Acute Care Hospitals | J5: Voluntary non-profit - Private | K5: Yes | L5: 2 | M5: 2 | O5: 77 | P5: 77 | Q5: 61 | R5: 83 | S5: 66 | T5: 66 | U5: 1177 | V5: 13 | W5: 45474 | X5: 45838 | Y5: 14.9 | Z5: No Different | AA5: 2792 | AB5: 13.9 | AC5: 15.9 | AE5: 45108 | AF5: 45473 | AG5: TRUE | AH5: TRUE | AI5: TRUE | AJ5: =IF(tblMergedCleaned[[#This Row],[Overall_Rating]]= "", "Unavailable", IF(tblMergedCleaned[[#This Row],[Overall_Rating]]<= 2, "Low (1-2)", IF(tblMergedCleaned[[#This Row],[Overall_Rating]]= 3, "Middle (3)", "High (4-5)" ) ) ) -> Low (1-2) | AK5: {=IF( tblMergedCleaned[[#This Row],[Overall_Rating]]="", "", --(tblMergedCleaned[[#This Row],[Overall_Rating]]<=2) )} -> 1 | AL5: =IF( tblMergedCleaned[[#This Row],[Definitely_Recommend_Pct]]="", "", --(tblMergedCleaned[[#This Row],[Definitely_Recommend_Pct]]<TX_Median_Recommend) ) -> 1 | AM5: =IF( tblMergedCleaned[[#This Row],[Readmission_Comparison]]="", "", --(tblMergedCleaned[[#This Row],[Readmission_Comparison]]="Worse") ) -> 0 | AN5: =COUNT( tblMergedCleaned[[#This Row],[Low_Rating_Flag]:[Worse_Readmission_Flag]] ) -> 3 | AO5: =SUM( tblMergedCleaned[[#This Row],[Low_Rating_Flag]:[Worse_Readmission_Flag]] ) -> 2 | AP5: =IF( tblMergedCleaned[[#This Row],[Signals_Available_Count]]<3, "Limited data", IF( tblMergedCleaned[[#This Row],[Screening_Signal_Count]]=3, "Priority 1", IF( tblMergedCleaned[[#This Row],[Screening_Signal_Count]]=2, "Priority 2", IF( tblMergedCleaned[[#This Row],[Screening_Signal_Count]]=1, "Monitor", "No flagged signals" ) ) ) ) -> Priority 2 | AQ5: =IF( tblMergedCleaned[[#This Row],[Definitely_Recommend_Pct]]="", "Unavailable", IF( tblMergedCleaned[[#This Row],[Definitely_Recommend_Pct]]<=TX_Recommend_Q1, "Q1 - Lowest", IF( tblMergedCleaned[[#This Row],[Definitely_Recommend_Pct]]<=TX_Median_Recommend, "Q2", IF( tblMergedCleaned[[#This Row],[Definitely_Recommend_Pct]]<=TX_Recommend_Q3, "Q3", "Q4 - Highest" ) ) ) ) -> Q1 - Lowest | AR5: =IF( tblMergedCleaned[[#This Row],[Definitely_Recommend_Pct]]="", "", tblMergedCleaned[[#This Row],[Definitely_Recommend_Pct]]-TX_Median_Recommend ) -> -5 | AS5: =IF( tblMergedCleaned[[#This Row],[Readmission_Rate_Pct]]="", "", tblMergedCleaned[[#This Row],[Readmission_Rate_Pct]]-TX_Median_Readmission ) -> 0
A6: 450015 | B6: PARKLAND HEALTH & HOSPITAL SYSTEM | C6: 5200 HARRY HINES BLVD | D6: DALLAS | E6: TX | F6: 75235 | G6: DALLAS | H6: (214) 590-8000 | I6: Acute Care Hospitals | J6: Government - Hospital District or Authority | K6: Yes | L6: 3 | M6: 3 | O6: 73 | P6: 76 | Q6: 56 | R6: 85 | S6: 70 | T6: 70 | U6: 1727 | V6: 6 | W6: 45474 | X6: 45838 | Y6: 14.7 | Z6: No Different | AA6: 893 | AB6: 13.5 | AC6: 16.1 | AE6: 45108 | AF6: 45473 | AG6: TRUE | AH6: TRUE | AI6: TRUE | AJ6: =IF(tblMergedCleaned[[#This Row],[Overall_Rating]]= "", "Unavailable", IF(tblMergedCleaned[[#This Row],[Overall_Rating]]<= 2, "Low (1-2)", IF(tblMergedCleaned[[#This Row],[Overall_Rating]]= 3, "Middle (3)", "High (4-5)" ) ) ) -> Middle (3) | AK6: {=IF( tblMergedCleaned[[#This Row],[Overall_Rating]]="", "", --(tblMergedCleaned[[#This Row],[Overall_Rating]]<=2) )} -> 0 | AL6: =IF( tblMergedCleaned[[#This Row],[Definitely_Recommend_Pct]]="", "", --(tblMergedCleaned[[#This Row],[Definitely_Recommend_Pct]]<TX_Median_Recommend) ) -> 1 | AM6: =IF( tblMergedCleaned[[#This Row],[Readmission_Comparison]]="", "", --(tblMergedCleaned[[#This Row],[Readmission_Comparison]]="Worse") ) -> 0 | AN6: =COUNT( tblMergedCleaned[[#This Row],[Low_Rating_Flag]:[Worse_Readmission_Flag]] ) -> 3 | AO6: =SUM( tblMergedCleaned[[#This Row],[Low_Rating_Flag]:[Worse_Readmission_Flag]] ) -> 1 | AP6: =IF( tblMergedCleaned[[#This Row],[Signals_Available_Count]]<3, "Limited data", IF( tblMergedCleaned[[#This Row],[Screening_Signal_Count]]=3, "Priority 1", IF( tblMergedCleaned[[#This Row],[Screening_Signal_Count]]=2, "Priority 2", IF( tblMergedCleaned[[#This Row],[Screening_Signal_Count]]=1, "Monitor", "No flagged signals" ) ) ) ) -> Monitor | AQ6: =IF( tblMergedCleaned[[#This Row],[Definitely_Recommend_Pct]]="", "Unavailable", IF( tblMergedCleaned[[#This Row],[Definitely_Recommend_Pct]]<=TX_Recommend_Q1, "Q1 - Lowest", IF( tblMergedCleaned[[#This Row],[Definitely_Recommend_Pct]]<=TX_Median_Recommend, "Q2", IF( tblMergedCleaned[[#This Row],[Definitely_Recommend_Pct]]<=TX_Recommend_Q3, "Q3", "Q4 - Highest" ) ) ) ) -> Q2 | AR6: =IF( tblMergedCleaned[[#This Row],[Definitely_Recommend_Pct]]="", "", tblMergedCleaned[[#This Row],[Definitely_Recommend_Pct]]-TX_Median_Recommend ) -> -1 | AS6: =IF( tblMergedCleaned[[#This Row],[Readmission_Rate_Pct]]="", "", tblMergedCleaned[[#This Row],[Readmission_Rate_Pct]]-TX_Median_Readmission ) -> -0.2
A7: 450018 | B7: UNIVERSITY OF TEXAS MEDICAL BRANCH GALVESTON | C7: 301 UNIVERSITY BOULEVARD | D7: GALVESTON | E7: TX | F7: 77555 | G7: GALVESTON | H7: (409) 772-1011 | I7: Acute Care Hospitals | J7: Government - State | K7: Yes | L7: 3 | M7: 3 | O7: 77 | P7: 76 | Q7: 61 | R7: 85 | S7: 74 | T7: 72 | U7: 1342 | V7: 11 | W7: 45474 | X7: 45838 | Y7: 16 | Z7: No Different | AA7: 3474 | AB7: 15 | AC7: 16.9 | AE7: 45108 | AF7: 45473 | AG7: TRUE | AH7: TRUE | AI7: TRUE | AJ7: =IF(tblMergedCleaned[[#This Row],[Overall_Rating]]= "", "Unavailable", IF(tblMergedCleaned[[#This Row],[Overall_Rating]]<= 2, "Low (1-2)", IF(tblMergedCleaned[[#This Row],[Overall_Rating]]= 3, "Middle (3)", "High (4-5)" ) ) ) -> Middle (3) | AK7: {=IF( tblMergedCleaned[[#This Row],[Overall_Rating]]="", "", --(tblMergedCleaned[[#This Row],[Overall_Rating]]<=2) )} -> 0 | AL7: =IF( tblMergedCleaned[[#This Row],[Definitely_Recommend_Pct]]="", "", --(tblMergedCleaned[[#This Row],[Definitely_Recommend_Pct]]<TX_Median_Recommend) ) -> 0 | AM7: =IF( tblMergedCleaned[[#This Row],[Readmission_Comparison]]="", "", --(tblMergedCleaned[[#This Row],[Readmission_Comparison]]="Worse") ) -> 0 | AN7: =COUNT( tblMergedCleaned[[#This Row],[Low_Rating_Flag]:[Worse_Readmission_Flag]] ) -> 3 | AO7: =SUM( tblMergedCleaned[[#This Row],[Low_Rating_Flag]:[Worse_Readmission_Flag]] ) -> 0 | AP7: =IF( tblMergedCleaned[[#This Row],[Signals_Available_Count]]<3, "Limited data", IF( tblMergedCleaned[[#This Row],[Screening_Signal_Count]]=3, "Priority 1", IF( tblMergedCleaned[[#This Row],[Screening_Signal_Count]]=2, "Priority 2", IF( tblMergedCleaned[[#This Row],[Screening_Signal_Count]]=1, "Monitor", "No flagged signals" ) ) ) ) -> No flagged signals | AQ7: =IF( tblMergedCleaned[[#This Row],[Definitely_Recommend_Pct]]="", "Unavailable", IF( tblMergedCleaned[[#This Row],[Definitely_Recommend_Pct]]<=TX_Recommend_Q1, "Q1 - Lowest", IF( tblMergedCleaned[[#This Row],[Definitely_Recommend_Pct]]<=TX_Median_Recommend, "Q2", IF( tblMergedCleaned[[#This Row],[Definitely_Recommend_Pct]]<=TX_Recommend_Q3, "Q3", "Q4 - Highest" ) ) ) ) -> Q3 | AR7: =IF( tblMergedCleaned[[#This Row],[Definitely_Recommend_Pct]]="", "", tblMergedCleaned[[#This Row],[Definitely_Recommend_Pct]]-TX_Median_Recommend ) -> 1 | AS7: =IF( tblMergedCleaned[[#This Row],[Readmission_Rate_Pct]]="", "", tblMergedCleaned[[#This Row],[Readmission_Rate_Pct]]-TX_Median_Readmission ) -> 1.1
A8: 450021 | B8: BAYLOR UNIVERSITY MEDICAL CENTER | C8: 3500 GASTON AVE | D8: DALLAS | E8: TX | F8: 75246 | G8: DALLAS | H8: (214) 820-8082 | I8: Acute Care Hospitals | J8: Voluntary non-profit - Private | K8: Yes | L8: 4 | M8: 4 | O8: 78 | P8: 80 | Q8: 60 | R8: 87 | S8: 71 | T8: 74 | U8: 2284 | V8: 12 | W8: 45474 | X8: 45838 | Y8: 13.9 | Z8: Better | AA8: 4591 | AB8: 13.1 | AC8: 14.7 | AE8: 45108 | AF8: 45473 | AG8: TRUE | AH8: TRUE | AI8: TRUE | AJ8: =IF(tblMergedCleaned[[#This Row],[Overall_Rating]]= "", "Unavailable", IF(tblMergedCleaned[[#This Row],[Overall_Rating]]<= 2, "Low (1-2)", IF(tblMergedCleaned[[#This Row],[Overall_Rating]]= 3, "Middle (3)", "High (4-5)" ) ) ) -> High (4-5) | AK8: {=IF( tblMergedCleaned[[#This Row],[Overall_Rating]]="", "", --(tblMergedCleaned[[#This Row],[Overall_Rating]]<=2) )} -> 0 | AL8: =IF( tblMergedCleaned[[#This Row],[Definitely_Recommend_Pct]]="", "", --(tblMergedCleaned[[#This Row],[Definitely_Recommend_Pct]]<TX_Median_Recommend) ) -> 0 | AM8: =IF( tblMergedCleaned[[#This Row],[Readmission_Comparison]]="", "", --(tblMergedCleaned[[#This Row],[Readmission_Comparison]]="Worse") ) -> 0 | AN8: =COUNT( tblMergedCleaned[[#This Row],[Low_Rating_Flag]:[Worse_Readmission_Flag]] ) -> 3 | AO8: =SUM( tblMergedCleaned[[#This Row],[Low_Rating_Flag]:[Worse_Readmission_Flag]] ) -> 0 | AP8: =IF( tblMergedCleaned[[#This Row],[Signals_Available_Count]]<3, "Limited data", IF( tblMergedCleaned[[#This Row],[Screening_Signal_Count]]=3, "Priority 1", IF( tblMergedCleaned[[#This Row],[Screening_Signal_Count]]=2, "Priority 2", IF( tblMergedCleaned[[#This Row],[Screening_Signal_Count]]=1, "Monitor", "No flagged signals" ) ) ) ) -> No flagged signals | AQ8: =IF( tblMergedCleaned[[#This Row],[Definitely_Recommend_Pct]]="", "Unavailable", IF( tblMergedCleaned[[#This Row],[Definitely_Recommend_Pct]]<=TX_Recommend_Q1, "Q1 - Lowest", IF( tblMergedCleaned[[#This Row],[Definitely_Recommend_Pct]]<=TX_Median_Recommend, "Q2", IF( tblMergedCleaned[[#This Row],[Definitely_Recommend_Pct]]<=TX_Recommend_Q3, "Q3", "Q4 - Highest" ) ) ) ) -> Q3 | AR8: =IF( tblMergedCleaned[[#This Row],[Definitely_Recommend_Pct]]="", "", tblMergedCleaned[[#This Row],[Definitely_Recommend_Pct]]-TX_Median_Recommend ) -> 3 | AS8: =IF( tblMergedCleaned[[#This Row],[Readmission_Rate_Pct]]="", "", tblMergedCleaned[[#This Row],[Readmission_Rate_Pct]]-TX_Median_Readmission ) -> -1
A9: 450023 | B9: CITIZENS MEDICAL CENTER | C9: 2701 HOSPITAL DRIVE | D9: VICTORIA | E9: TX | F9: 77901 | G9: VICTORIA | H9: (361) 573-9181 | I9: Acute Care Hospitals | J9: Voluntary non-profit - Other | K9: Yes | L9: 3 | M9: 3 | O9: 80 | P9: 79 | Q9: 61 | R9: 83 | S9: 73 | T9: 73 | U9: 882 | V9: 19 | W9: 45474 | X9: 45838 | Y9: 14.7 | Z9: No Different | AA9: 1380 | AB9: 13.5 | AC9: 16.1 | AE9: 45108 | AF9: 45473 | AG9: TRUE | AH9: TRUE | AI9: TRUE | AJ9: =IF(tblMergedCleaned[[#This Row],[Overall_Rating]]= "", "Unavailable", IF(tblMergedCleaned[[#This Row],[Overall_Rating]]<= 2, "Low (1-2)", IF(tblMergedCleaned[[#This Row],[Overall_Rating]]= 3, "Middle (3)", "High (4-5)" ) ) ) -> Middle (3) | AK9: {=IF( tblMergedCleaned[[#This Row],[Overall_Rating]]="", "", --(tblMergedCleaned[[#This Row],[Overall_Rating]]<=2) )} -> 0 | AL9: =IF( tblMergedCleaned[[#This Row],[Definitely_Recommend_Pct]]="", "", --(tblMergedCleaned[[#This Row],[Definitely_Recommend_Pct]]<TX_Median_Recommend) ) -> 0 | AM9: =IF( tblMergedCleaned[[#This Row],[Readmission_Comparison]]="", "", --(tblMergedCleaned[[#This Row],[Readmission_Comparison]]="Worse") ) -> 0 | AN9: =COUNT( tblMergedCleaned[[#This Row],[Low_Rating_Flag]:[Worse_Readmission_Flag]] ) -> 3 | AO9: =SUM( tblMergedCleaned[[#This Row],[Low_Rating_Flag]:[Worse_Readmission_Flag]] ) -> 0 | AP9: =IF( tblMergedCleaned[[#This Row],[Signals_Available_Count]]<3, "Limited data", IF( tblMergedCleaned[[#This Row],[Screening_Signal_Count]]=3, "Priority 1", IF( tblMergedCleaned[[#This Row],[Screening_Signal_Count]]=2, "Priority 2", IF( tblMergedCleaned[[#This Row],[Screening_Signal_Count]]=1, "Monitor", "No flagged signals" ) ) ) ) -> No flagged signals | AQ9: =IF( tblMergedCleaned[[#This Row],[Definitely_Recommend_Pct]]="", "Unavailable", IF( tblMergedCleaned[[#This Row],[Definitely_Recommend_Pct]]<=TX_Recommend_Q1, "Q1 - Lowest", IF( tblMergedCleaned[[#This Row],[Definitely_Recommend_Pct]]<=TX_Median_Recommend, "Q2", IF( tblMergedCleaned[[#This Row],[Definitely_Recommend_Pct]]<=TX_Recommend_Q3, "Q3", "Q4 - Highest" ) ) ) ) -> Q3 | AR9: =IF( tblMergedCleaned[[#This Row],[Definitely_Recommend_Pct]]="", "", tblMergedCleaned[[#This Row],[Definitely_Recommend_Pct]]-TX_Median_Recommend ) -> 2 | AS9: =IF( tblMergedCleaned[[#This Row],[Readmission_Rate_Pct]]="", "", tblMergedCleaned[[#This Row],[Readmission_Rate_Pct]]-TX_Median_Readmission ) -> -0.2
A10: 450024 | B10: UNIVERSITY MEDICAL CENTER OF EL PASO | C10: 4815 ALAMEDA AVE | D10: EL PASO | E10: TX | F10: 79905 | G10: EL PASO | H10: (915) 521-7602 | I10: Acute Care Hospitals | J10: Physician | K10: Yes | L10: 3 | M10: 3 | O10: 73 | P10: 75 | Q10: 56 | R10: 84 | S10: 68 | T10: 70 | U10: 2423 | V10: 24 | W10: 45474 | X10: 45838 | Y10: 15.4 | Z10: No Different | AA10: 906 | AB10: 14.1 | AC10: 16.8 | AE10: 45108 | AF10: 45473 | AG10: TRUE | AH10: TRUE | AI10: TRUE | AJ10: =IF(tblMergedCleaned[[#This Row],[Overall_Rating]]= "", "Unavailable", IF(tblMergedCleaned[[#This Row],[Overall_Rating]]<= 2, "Low (1-2)", IF(tblMergedCleaned[[#This Row],[Overall_Rating]]= 3, "Middle (3)", "High (4-5)" ) ) ) -> Middle (3) | AK10: {=IF( tblMergedCleaned[[#This Row],[Overall_Rating]]="", "", --(tblMergedCleaned[[#This Row],[Overall_Rating]]<=2) )} -> 0 | AL10: =IF( tblMergedCleaned[[#This Row],[Definitely_Recommend_Pct]]="", "", --(tblMergedCleaned[[#This Row],[Definitely_Recommend_Pct]]<TX_Median_Recommend) ) -> 1 | AM10: =IF( tblMergedCleaned[[#This Row],[Readmission_Comparison]]="", "", --(tblMergedCleaned[[#This Row],[Readmission_Comparison]]="Worse") ) -> 0 | AN10: =COUNT( tblMergedCleaned[[#This Row],[Low_Rating_Flag]:[Worse_Readmission_Flag]] ) -> 3 | AO10: =SUM( tblMergedCleaned[[#This Row],[Low_Rating_Flag]:[Worse_Readmission_Flag]] ) -> 1 | AP10: =IF( tblMergedCleaned[[#This Row],[Signals_Available_Count]]<3, "Limited data", IF( tblMergedCleaned[[#This Row],[Screening_Signal_Count]]=3, "Priority 1", IF( tblMergedCleaned[[#This Row],[Screening_Signal_Count]]=2, "Priority 2", IF( tblMergedCleaned[[#This Row],[Screening_Signal_Count]]=1, "Monitor", "No flagged signals" ) ) ) ) -> Monitor | AQ10: =IF( tblMergedCleaned[[#This Row],[Definitely_Recommend_Pct]]="", "Unavailable", IF( tblMergedCleaned[[#This Row],[Definitely_Recommend_Pct]]<=TX_Recommend_Q1, "Q1 - Lowest", IF( tblMergedCleaned[[#This Row],[Definitely_Recommend_Pct]]<=TX_Median_Recommend, "Q2", IF( tblMergedCleaned[[#This Row],[Definitely_Recommend_Pct]]<=TX_Recommend_Q3, "Q3", "Q4 - Highest" ) ) ) ) -> Q2 | AR10: =IF( tblMergedCleaned[[#This Row],[Definitely_Recommend_Pct]]="", "", tblMergedCleaned[[#This Row],[Definitely_Recommend_Pct]]-TX_Median_Recommend ) -> -1 | AS10: =IF( tblMergedCleaned[[#This Row],[Readmission_Rate_Pct]]="", "", tblMergedCleaned[[#This Row],[Readmission_Rate_Pct]]-TX_Median_Readmission ) -> 0.5
A11: 450028 | B11: VALLEY BAPTIST MEDICAL CENTER- BROWNSVILLE | C11: 1040 W JEFFERSON ST | D11: BROWNSVILLE | E11: TX | F11: 78520 | G11: CAMERON | H11: (956) 544-1400 | I11: Acute Care Hospitals | J11: Proprietary | K11: Yes | L11: 3 | M11: 3 | O11: 66 | P11: 69 | Q11: 51 | R11: 81 | S11: 58 | T11: 58 | U11: 410 | V11: 8 | W11: 45474 | X11: 45838 | Y11: 15.4 | Z11: No Different | AA11: 710 | AB11: 14 | AC11: 16.9 | AE11: 45108 | AF11: 45473 | AG11: TRUE | AH11: TRUE | AI11: TRUE | AJ11: =IF(tblMergedCleaned[[#This Row],[Overall_Rating]]= "", "Unavailable", IF(tblMergedCleaned[[#This Row],[Overall_Rating]]<= 2, "Low (1-2)", IF(tblMergedCleaned[[#This Row],[Overall_Rating]]= 3, "Middle (3)", "High (4-5)" ) ) ) -> Middle (3) | AK11: {=IF( tblMergedCleaned[[#This Row],[Overall_Rating]]="", "", --(tblMergedCleaned[[#This Row],[Overall_Rating]]<=2) )} -> 0 | AL11: =IF( tblMergedCleaned[[#This Row],[Definitely_Recommend_Pct]]="", "", --(tblMergedCleaned[[#This Row],[Definitely_Recommend_Pct]]<TX_Median_Recommend) ) -> 1 | AM11: =IF( tblMergedCleaned[[#This Row],[Readmission_Comparison]]="", "", --(tblMergedCleaned[[#This Row],[Readmission_Comparison]]="Worse") ) -> 0 | AN11: =COUNT( tblMergedCleaned[[#This Row],[Low_Rating_Flag]:[Worse_Readmission_Flag]] ) -> 3 | AO11: =SUM( tblMergedCleaned[[#This Row],[Low_Rating_Flag]:[Worse_Readmission_Flag]] ) -> 1 | AP11: =IF( tblMergedCleaned[[#This Row],[Signals_Available_Count]]<3, "Limited data", IF( tblMergedCleaned[[#This Row],[Screening_Signal_Count]]=3, "Priority 1", IF( tblMergedCleaned[[#This Row],[Screening_Signal_Count]]=2, "Priority 2", IF( tblMergedCleaned[[#This Row],[Screening_Signal_Count]]=1, "Monitor", "No flagged signals" ) ) ) ) -> Monitor | AQ11: =IF( tblMergedCleaned[[#This Row],[Definitely_Recommend_Pct]]="", "Unavailable", IF( tblMergedCleaned[[#This Row],[Definitely_Recommend_Pct]]<=TX_Recommend_Q1, "Q1 - Lowest", IF( tblMergedCleaned[[#This Row],[Definitely_Recommend_Pct]]<=TX_Median_Recommend, "Q2", IF( tblMergedCleaned[[#This Row],[Definitely_Recommend_Pct]]<=TX_Recommend_Q3, "Q3", "Q4 - Highest" ) ) ) ) -> Q1 - Lowest | AR11: =IF( tblMergedCleaned[[#This Row],[Definitely_Recommend_Pct]]="", "", tblMergedCleaned[[#This Row],[Definitely_Recommend_Pct]]-TX_Median_Recommend ) -> -13 | AS11: =IF( tblMergedCleaned[[#This Row],[Readmission_Rate_Pct]]="", "", tblMergedCleaned[[#This Row],[Readmission_Rate_Pct]]-TX_Median_Readmission ) -> 0.5
A12: 450029 | B12: LAREDO MEDICAL CENTER | C12: 1700 EAST SAUNDERS | D12: LAREDO | E12: TX | F12: 78044 | G12: WEBB | H12: (956) 796-5000 | I12: Acute Care Hospitals | J12: Proprietary | K12: Yes | L12: 4 | M12: 4 | O12: 74 | P12: 75 | Q12: 56 | R12: 80 | S12: 59 | T12: 59 | U12: 387 | V12: 7 | W12: 45474 | X12: 45838 | Y12: 15.1 | Z12: No Different | AA12: 1371 | AB12: 13.9 | AC12: 16.2 | AE12: 45108 | AF12: 45473 | AG12: TRUE | AH12: TRUE | AI12: TRUE | AJ12: =IF(tblMergedCleaned[[#This Row],[Overall_Rating]]= "", "Unavailable", IF(tblMergedCleaned[[#This Row],[Overall_Rating]]<= 2, "Low (1-2)", IF(tblMergedCleaned[[#This Row],[Overall_Rating]]= 3, "Middle (3)", "High (4-5)" ) ) ) -> High (4-5) | AK12: {=IF( tblMergedCleaned[[#This Row],[Overall_Rating]]="", "", --(tblMergedCleaned[[#This Row],[Overall_Rating]]<=2) )} -> 0 | AL12: =IF( tblMergedCleaned[[#This Row],[Definitely_Recommend_Pct]]="", "", --(tblMergedCleaned[[#This Row],[Definitely_Recommend_Pct]]<TX_Median_Recommend) ) -> 1 | AM12: =IF( tblMergedCleaned[[#This Row],[Readmission_Comparison]]="", "", --(tblMergedCleaned[[#This Row],[Readmission_Comparison]]="Worse") ) -> 0 | AN12: =COUNT( tblMergedCleaned[[#This Row],[Low_Rating_Flag]:[Worse_Readmission_Flag]] ) -> 3 | AO12: =SUM( tblMergedCleaned[[#This Row],[Low_Rating_Flag]:[Worse_Readmission_Flag]] ) -> 1 | AP12: =IF( tblMergedCleaned[[#This Row],[Signals_Available_Count]]<3, "Limited data", IF( tblMergedCleaned[[#This Row],[Screening_Signal_Count]]=3, "Priority 1", IF( tblMergedCleaned[[#This Row],[Screening_Signal_Count]]=2, "Priority 2", IF( tblMergedCleaned[[#This Row],[Screening_Signal_Count]]=1, "Monitor", "No flagged signals" ) ) ) ) -> Monitor | AQ12: =IF( tblMergedCleaned[[#This Row],[Definitely_Recommend_Pct]]="", "Unavailable", IF( tblMergedCleaned[[#This Row],[Definitely_Recommend_Pct]]<=TX_Recommend_Q1, "Q1 - Lowest", IF( tblMergedCleaned[[#This Row],[Definitely_Recommend_Pct]]<=TX_Median_Recommend, "Q2", IF( tblMergedCleaned[[#This Row],[Definitely_Recommend_Pct]]<=TX_Recommend_Q3, "Q3", "Q4 - Highest" ) ) ) ) -> Q1 - Lowest | AR12: =IF( tblMergedCleaned[[#This Row],[Definitely_Recommend_Pct]]="", "", tblMergedCleaned[[#This Row],[Definitely_Recommend_Pct]]-TX_Median_Recommend ) -> -12 | AS12: =IF( tblMergedCleaned[[#This Row],[Readmission_Rate_Pct]]="", "", tblMergedCleaned[[#This Row],[Readmission_Rate_Pct]]-TX_Median_Readmission ) -> 0.2
A13: 450032 | B13: CHRISTUS GOOD SHEPHERD MEDICAL CENTER | C13: 700 E MARSHALL AVE | D13: LONGVIEW | E13: TX | F13: 75601 | G13: GREGG | H13: (903) 927-6712 | I13: Acute Care Hospitals | J13: Voluntary non-profit - Private | K13: Yes | L13: 4 | M13: 4 | O13: 81 | P13: 78 | Q13: 67 | R13: 85 | S13: 72 | T13: 71 | U13: 486 | V13: 15 | W13: 45474 | X13: 45838 | Y13: 16.4 | Z13: Worse | AA13: 2659 | AB13: 15.4 | AC13: 17.4 | AE13: 45108 | AF13: 45473 | AG13: TRUE | AH13: TRUE | AI13: TRUE | AJ13: =IF(tblMergedCleaned[[#This Row],[Overall_Rating]]= "", "Unavailable", IF(tblMergedCleaned[[#This Row],[Overall_Rating]]<= 2, "Low (1-2)", IF(tblMergedCleaned[[#This Row],[Overall_Rating]]= 3, "Middle (3)", "High (4-5)" ) ) ) -> High (4-5) | AK13: {=IF( tblMergedCleaned[[#This Row],[Overall_Rating]]="", "", --(tblMergedCleaned[[#This Row],[Overall_Rating]]<=2) )} -> 0 | AL13: =IF( tblMergedCleaned[[#This Row],[Definitely_Recommend_Pct]]="", "", --(tblMergedCleaned[[#This Row],[Definitely_Recommend_Pct]]<TX_Median_Recommend) ) -> 0 | AM13: =IF( tblMergedCleaned[[#This Row],[Readmission_Comparison]]="", "", --(tblMergedCleaned[[#This Row],[Readmission_Comparison]]="Worse") ) -> 1 | AN13: =COUNT( tblMergedCleaned[[#This Row],[Low_Rating_Flag]:[Worse_Readmission_Flag]] ) -> 3 | AO13: =SUM( tblMergedCleaned[[#This Row],[Low_Rating_Flag]:[Worse_Readmission_Flag]] ) -> 1 | AP13: =IF( tblMergedCleaned[[#This Row],[Signals_Available_Count]]<3, "Limited data", IF( tblMergedCleaned[[#This Row],[Screening_Signal_Count]]=3, "Priority 1", IF( tblMergedCleaned[[#This Row],[Screening_Signal_Count]]=2, "Priority 2", IF( tblMergedCleaned[[#This Row],[Screening_Signal_Count]]=1, "Monitor", "No flagged signals" ) ) ) ) -> Monitor | AQ13: =IF( tblMergedCleaned[[#This Row],[Definitely_Recommend_Pct]]="", "Unavailable", IF( tblMergedCleaned[[#This Row],[Definitely_Recommend_Pct]]<=TX_Recommend_Q1, "Q1 - Lowest", IF( tblMergedCleaned[[#This Row],[Definitely_Recommend_Pct]]<=TX_Median_Recommend, "Q2", IF( tblMergedCleaned[[#This Row],[Definitely_Recommend_Pct]]<=TX_Recommend_Q3, "Q3", "Q4 - Highest" ) ) ) ) -> Q2 | AR13: =IF( tblMergedCleaned[[#This Row],[Definitely_Recommend_Pct]]="", "", tblMergedCleaned[[#This Row],[Definitely_Recommend_Pct]]-TX_Median_Recommend ) -> 0 | AS13: =IF( tblMergedCleaned[[#This Row],[Readmission_Rate_Pct]]="", "", tblMergedCleaned[[#This Row],[Readmission_Rate_Pct]]-TX_Median_Readmission ) -> 1.5
... A18: 450040 | B18: COVENANT MEDICAL CENTER | C18: 3615 19TH STREET | D18: LUBBOCK | E18: TX | F18: 79410 | G18: LUBBOCK | H18: (806) 725-4431 | I18: Acute Care Hospitals | J18: Voluntary non-profit - Private | K18: Yes | L18: 3 | M18: 3 | O18: 76 | P18: 75 | Q18: 60 | R18: 85 | S18: 69 | T18: 70 | U18: 757 | V18: 18 | W18: 45474 | X18: 45838 | Y18: 13.5 | Z18: Better | AA18: 3522 | AB18: 12.7 | AC18: 14.5 | AE18: 45108 | AF18: 45473 | AG18: TRUE | AH18: TRUE | AI18: TRUE | AJ18: =IF(tblMergedCleaned[[#This Row],[Overall_Rating]]= "", "Unavailable", IF(tblMergedCleaned[[#This Row],[Overall_Rating]]<= 2, "Low (1-2)", IF(tblMergedCleaned[[#This Row],[Overall_Rating]]= 3, "Middle (3)", "High (4-5)" ) ) ) -> Middle (3) | AK18: {=IF( tblMergedCleaned[[#This Row],[Overall_Rating]]="", "", --(tblMergedCleaned[[#This Row],[Overall_Rating]]<=2) )} -> 0 | AL18: =IF( tblMergedCleaned[[#This Row],[Definitely_Recommend_Pct]]="", "", --(tblMergedCleaned[[#This Row],[Definitely_Recommend_Pct]]<TX_Median_Recommend) ) -> 1 | AM18: =IF( tblMergedCleaned[[#This Row],[Readmission_Comparison]]="", "", --(tblMergedCleaned[[#This Row],[Readmission_Comparison]]="Worse") ) -> 0 | AN18: =COUNT( tblMergedCleaned[[#This Row],[Low_Rating_Flag]:[Worse_Readmission_Flag]] ) -> 3 | AO18: =SUM( tblMergedCleaned[[#This Row],[Low_Rating_Flag]:[Worse_Readmission_Flag]] ) -> 1 | AP18: =IF( tblMergedCleaned[[#This Row],[Signals_Available_Count]]<3, "Limited data", IF( tblMergedCleaned[[#This Row],[Screening_Signal_Count]]=3, "Priority 1", IF( tblMergedCleaned[[#This Row],[Screening_Signal_Count]]=2, "Priority 2", IF( tblMergedCleaned[[#This Row],[Screening_Signal_Count]]=1, "Monitor", "No flagged signals" ) ) ) ) -> Monitor | AQ18: =IF( tblMergedCleaned[[#This Row],[Definitely_Recommend_Pct]]="", "Unavailable", IF( tblMergedCleaned[[#This Row],[Definitely_Recommend_Pct]]<=TX_Recommend_Q1, "Q1 - Lowest", IF( tblMergedCleaned[[#This Row],[Definitely_Recommend_Pct]]<=TX_Median_Recommend, "Q2", IF( tblMergedCleaned[[#This Row],[Definitely_Recommend_Pct]]<=TX_Recommend_Q3, "Q3", "Q4 - Highest" ) ) ) ) -> Q2 | AR18: =IF( tblMergedCleaned[[#This Row],[Definitely_Recommend_Pct]]="", "", tblMergedCleaned[[#This Row],[Definitely_Recommend_Pct]]-TX_Median_Recommend ) -> -1 | AS18: =IF( tblMergedCleaned[[#This Row],[Readmission_Rate_Pct]]="", "", tblMergedCleaned[[#This Row],[Readmission_Rate_Pct]]-TX_Median_Readmission ) -> -1.4
A19: 450042 | B19: ASCENSION PROVIDENCE | C19: 6901 MEDICAL PARKWAY | D19: WACO | E19: TX | F19: 76712 | G19: MC LENNAN | H19: (254) 751-4000 | I19: Acute Care Hospitals | J19: Voluntary non-profit - Private | K19: Yes | L19: 2 | M19: 2 | N19: 29 | O19: 76 | P19: 80 | Q19: 61 | R19: 87 | S19: 73 | T19: 72 | U19: 269 | V19: 15 | W19: 45474 | X19: 45838 | Y19: 14.2 | Z19: No Different | AA19: 1091 | AB19: 13 | AC19: 15.1 | AD19: 29 | AE19: 45108 | AF19: 45473 | AG19: TRUE | AH19: TRUE | AI19: TRUE | AJ19: =IF(tblMergedCleaned[[#This Row],[Overall_Rating]]= "", "Unavailable", IF(tblMergedCleaned[[#This Row],[Overall_Rating]]<= 2, "Low (1-2)", IF(tblMergedCleaned[[#This Row],[Overall_Rating]]= 3, "Middle (3)", "High (4-5)" ) ) ) -> Low (1-2) | AK19: {=IF( tblMergedCleaned[[#This Row],[Overall_Rating]]="", "", --(tblMergedCleaned[[#This Row],[Overall_Rating]]<=2) )} -> 1 | AL19: =IF( tblMergedCleaned[[#This Row],[Definitely_Recommend_Pct]]="", "", --(tblMergedCleaned[[#This Row],[Definitely_Recommend_Pct]]<TX_Median_Recommend) ) -> 0 | AM19: =IF( tblMergedCleaned[[#This Row],[Readmission_Comparison]]="", "", --(tblMergedCleaned[[#This Row],[Readmission_Comparison]]="Worse") ) -> 0 | AN19: =COUNT( tblMergedCleaned[[#This Row],[Low_Rating_Flag]:[Worse_Readmission_Flag]] ) -> 3 | AO19: =SUM( tblMergedCleaned[[#This Row],[Low_Rating_Flag]:[Worse_Readmission_Flag]] ) -> 1 | AP19: =IF( tblMergedCleaned[[#This Row],[Signals_Available_Count]]<3, "Limited data", IF( tblMergedCleaned[[#This Row],[Screening_Signal_Count]]=3, "Priority 1", IF( tblMergedCleaned[[#This Row],[Screening_Signal_Count]]=2, "Priority 2", IF( tblMergedCleaned[[#This Row],[Screening_Signal_Count]]=1, "Monitor", "No flagged signals" ) ) ) ) -> Monitor | AQ19: =IF( tblMergedCleaned[[#This Row],[Definitely_Recommend_Pct]]="", "Unavailable", IF( tblMergedCleaned[[#This Row],[Definitely_Recommend_Pct]]<=TX_Recommend_Q1, "Q1 - Lowest", IF( tblMergedCleaned[[#This Row],[Definitely_Recommend_Pct]]<=TX_Median_Recommend, "Q2", IF( tblMergedCleaned[[#This Row],[Definitely_Recommend_Pct]]<=TX_Recommend_Q3, "Q3", "Q4 - Highest" ) ) ) ) -> Q3 | AR19: =IF( tblMergedCleaned[[#This Row],[Definitely_Recommend_Pct]]="", "", tblMergedCleaned[[#This Row],[Definitely_Recommend_Pct]]-TX_Median_Recommend ) -> 1 | AS19: =IF( tblMergedCleaned[[#This Row],[Readmission_Rate_Pct]]="", "", tblMergedCleaned[[#This Row],[Readmission_Rate_Pct]]-TX_Median_Readmission ) -> -0.7
A20: 450044 | B20: UT OF TEXAS SOUTHWESTERN UNIVERSITY HOSPITAL - WILLIAM P. CLEMENTS JR. | C20: 6201 HARRY HINES BLVD | D20: DALLAS | E20: TX | F20: 75390 | G20: DALLAS | H20: (214) 633-5555 | I20: Acute Care Hospitals | J20: Government - State | K20: Yes | L20: 4 | M20: 4 | O20: 80 | P20: 83 | Q20: 63 | R20: 90 | S20: 83 | T20: 85 | U20: 3232 | V20: 16 | W20: 45474 | X20: 45838 | Y20: 15.9 | Z20: Worse | AA20: 5428 | AB20: 15.1 | AC20: 16.7 | AE20: 45108 | AF20: 45473 | AG20: TRUE | AH20: TRUE | AI20: TRUE | AJ20: =IF(tblMergedCleaned[[#This Row],[Overall_Rating]]= "", "Unavailable", IF(tblMergedCleaned[[#This Row],[Overall_Rating]]<= 2, "Low (1-2)", IF(tblMergedCleaned[[#This Row],[Overall_Rating]]= 3, "Middle (3)", "High (4-5)" ) ) ) -> High (4-5) | AK20: {=IF( tblMergedCleaned[[#This Row],[Overall_Rating]]="", "", --(tblMergedCleaned[[#This Row],[Overall_Rating]]<=2) )} -> 0 | AL20: =IF( tblMergedCleaned[[#This Row],[Definitely_Recommend_Pct]]="", "", --(tblMergedCleaned[[#This Row],[Definitely_Recommend_Pct]]<TX_Median_Recommend) ) -> 0 | AM20: =IF( tblMergedCleaned[[#This Row],[Readmission_Comparison]]="", "", --(tblMergedCleaned[[#This Row],[Readmission_Comparison]]="Worse") ) -> 1 | AN20: =COUNT( tblMergedCleaned[[#This Row],[Low_Rating_Flag]:[Worse_Readmission_Flag]] ) -> 3 | AO20: =SUM( tblMergedCleaned[[#This Row],[Low_Rating_Flag]:[Worse_Readmission_Flag]] ) -> 1 | AP20: =IF( tblMergedCleaned[[#This Row],[Signals_Available_Count]]<3, "Limited data", IF( tblMergedCleaned[[#This Row],[Screening_Signal_Count]]=3, "Priority 1", IF( tblMergedCleaned[[#This Row],[Screening_Signal_Count]]=2, "Priority 2", IF( tblMergedCleaned[[#This Row],[Screening_Signal_Count]]=1, "Monitor", "No flagged signals" ) ) ) ) -> Monitor | AQ20: =IF( tblMergedCleaned[[#This Row],[Definitely_Recommend_Pct]]="", "Unavailable", IF( tblMergedCleaned[[#This Row],[Definitely_Recommend_Pct]]<=TX_Recommend_Q1, "Q1 - Lowest", IF( tblMergedCleaned[[#This Row],[Definitely_Recommend_Pct]]<=TX_Median_Recommend, "Q2", IF( tblMergedCleaned[[#This Row],[Definitely_Recommend_Pct]]<=TX_Recommend_Q3, "Q3", "Q4 - Highest" ) ) ) ) -> Q4 - Highest | AR20: =IF( tblMergedCleaned[[#This Row],[Definitely_Recommend_Pct]]="", "", tblMergedCleaned[[#This Row],[Definitely_Recommend_Pct]]-TX_Median_Recommend ) -> 14 | AS20: =IF( tblMergedCleaned[[#This Row],[Readmission_Rate_Pct]]="", "", tblMergedCleaned[[#This Row],[Readmission_Rate_Pct]]-TX_Median_Readmission ) -> 1
A21: 450046 | B21: CHRISTUS SPOHN HOSPITAL CORPUS CHRISTI | C21: 600 ELIZABETH STREET | D21: CORPUS CHRISTI | E21: TX | F21: 78404 | G21: NUECES | H21: (361) 902-4103 | I21: Acute Care Hospitals | J21: Voluntary non-profit - Private | K21: Yes | L21: 3 | M21: 3 | O21: 74 | P21: 74 | Q21: 56 | R21: 82 | S21: 71 | T21: 72 | U21: 415 | V21: 12 | W21: 45474 | X21: 45838 | Y21: 14.4 | Z21: No Different | AA21: 2388 | AB21: 13.5 | AC21: 15.5 | AE21: 45108 | AF21: 45473 | AG21: TRUE | AH21: TRUE | AI21: TRUE | AJ21: =IF(tblMergedCleaned[[#This Row],[Overall_Rating]]= "", "Unavailable", IF(tblMergedCleaned[[#This Row],[Overall_Rating]]<= 2, "Low (1-2)", IF(tblMergedCleaned[[#This Row],[Overall_Rating]]= 3, "Middle (3)", "High (4-5)" ) ) ) -> Middle (3) | AK21: {=IF( tblMergedCleaned[[#This Row],[Overall_Rating]]="", "", --(tblMergedCleaned[[#This Row],[Overall_Rating]]<=2) )} -> 0 | AL21: =IF( tblMergedCleaned[[#This Row],[Definitely_Recommend_Pct]]="", "", --(tblMergedCleaned[[#This Row],[Definitely_Recommend_Pct]]<TX_Median_Recommend) ) -> 0 | AM21: =IF( tblMergedCleaned[[#This Row],[Readmission_Comparison]]="", "", --(tblMergedCleaned[[#This Row],[Readmission_Comparison]]="Worse") ) -> 0 | AN21: =COUNT( tblMergedCleaned[[#This Row],[Low_Rating_Flag]:[Worse_Readmission_Flag]] ) -> 3 | AO21: =SUM( tblMergedCleaned[[#This Row],[Low_Rating_Flag]:[Worse_Readmission_Flag]] ) -> 0 | AP21: =IF( tblMergedCleaned[[#This Row],[Signals_Available_Count]]<3, "Limited data", IF( tblMergedCleaned[[#This Row],[Screening_Signal_Count]]=3, "Priority 1", IF( tblMergedCleaned[[#This Row],[Screening_Signal_Count]]=2, "Priority 2", IF( tblMergedCleaned[[#This Row],[Screening_Signal_Count]]=1, "Monitor", "No flagged signals" ) ) ) ) -> No flagged signals | AQ21: =IF( tblMergedCleaned[[#This Row],[Definitely_Recommend_Pct]]="", "Unavailable", IF( tblMergedCleaned[[#This Row],[Definitely_Recommend_Pct]]<=TX_Recommend_Q1, "Q1 - Lowest", IF( tblMergedCleaned[[#This Row],[Definitely_Recommend_Pct]]<=TX_Median_Recommend, "Q2", IF( tblMergedCleaned[[#This Row],[Definitely_Recommend_Pct]]<=TX_Recommend_Q3, "Q3", "Q4 - Highest" ) ) ) ) -> Q3 | AR21: =IF( tblMergedCleaned[[#This Row],[Definitely_Recommend_Pct]]="", "", tblMergedCleaned[[#This Row],[Definitely_Recommend_Pct]]-TX_Median_Recommend ) -> 1 | AS21: =IF( tblMergedCleaned[[#This Row],[Readmission_Rate_Pct]]="", "", tblMergedCleaned[[#This Row],[Readmission_Rate_Pct]]-TX_Median_Readmission ) -> -0.5
